2024-02-24T11:34:03.641773+0600, ERROR, An error has been caught in function '<module>', process 'MainProcess' (14949), thread 'MainThread' (140652604256256):
Traceback (most recent call last):

> File "/home/arch1tect/work/lab_4/lab_4.py", line 27, in <module>
    find()
    └ <function find at 0x7fec3ae8f7f0>

  File "/home/arch1tect/work/lab_4/lab_4.py", line 22, in find
    in_3 = i["l1PhysI"]["attributes"]["mtu"]
           └ {'l1PhysIf': {'attributes': {'adminSt': 'up', 'autoNeg': 'on', 'brkoutMap': 'none', 'bw': '0', 'childAction': '', 'delay': '1...

KeyError: 'l1PhysI'
